2018-07-04 20:41:55,984 ERROR: Exception on /equipment/add [GET] [in /home/kodi/Workspace/parky/venv/lib/python3.6/site-packages/flask/app.py:1761]
Traceback (most recent call last):
  File "/home/kodi/Workspace/parky/venv/lib/python3.6/site-packages/flask/app.py", line 2292, in wsgi_app
    response = self.full_dispatch_request()
  File "/home/kodi/Workspace/parky/venv/lib/python3.6/site-packages/flask/app.py", line 1815, in full_dispatch_request
    rv = self.handle_user_exception(e)
  File "/home/kodi/Workspace/parky/venv/lib/python3.6/site-packages/flask/app.py", line 1718, in handle_user_exception
    reraise(exc_type, exc_value, tb)
  File "/home/kodi/Workspace/parky/venv/lib/python3.6/site-packages/flask/_compat.py", line 35, in reraise
    raise value
  File "/home/kodi/Workspace/parky/venv/lib/python3.6/site-packages/flask/app.py", line 1813, in full_dispatch_request
    rv = self.dispatch_request()
  File "/home/kodi/Workspace/parky/venv/lib/python3.6/site-packages/flask/app.py", line 1799, in dispatch_request
    return self.view_functions[rule.endpoint](**req.view_args)
  File "/home/kodi/Workspace/parky/venv/lib/python3.6/site-packages/flask_login/utils.py", line 261, in decorated_view
    return func(*args, **kwargs)
  File "/home/kodi/Workspace/parky/app/routes.py", line 146, in add_equipment
    form.category.choices = [(c.key.id(), c.name) for c in Category.query.all()]
  File "/home/kodi/Workspace/parky/app/routes.py", line 146, in <listcomp>
    form.category.choices = [(c.key.id(), c.name) for c in Category.query.all()]
AttributeError: 'Category' object has no attribute 'key'
2018-07-04 20:42:31,171 INFO: Microblog startup [in /home/kodi/Workspace/parky/app/__init__.py:52]
2018-07-04 20:53:18,567 INFO: Microblog startup [in /home/kodi/Workspace/parky/app/__init__.py:52]
2018-07-04 20:53:38,789 INFO: Microblog startup [in /home/kodi/Workspace/parky/app/__init__.py:52]
2018-07-04 20:53:55,933 INFO: Microblog startup [in /home/kodi/Workspace/parky/app/__init__.py:52]
2018-07-04 20:54:02,443 INFO: Microblog startup [in /home/kodi/Workspace/parky/app/__init__.py:52]
2018-07-04 20:54:16,760 INFO: Microblog startup [in /home/kodi/Workspace/parky/app/__init__.py:52]
2018-07-04 20:56:12,883 INFO: Microblog startup [in /home/kodi/Workspace/parky/app/__init__.py:52]
2018-07-05 00:23:00,675 INFO: Microblog startup [in /home/kodi/Workspace/parky/app/__init__.py:52]
2018-07-05 00:23:06,528 INFO: Microblog startup [in /home/kodi/Workspace/parky/app/__init__.py:52]
2018-07-05 00:23:16,222 INFO: Microblog startup [in /home/kodi/Workspace/parky/app/__init__.py:52]
2018-07-05 00:23:22,412 INFO: Microblog startup [in /home/kodi/Workspace/parky/app/__init__.py:52]
2018-07-05 00:24:31,179 INFO: Microblog startup [in /home/kodi/Workspace/parky/app/__init__.py:52]
2018-07-05 00:28:29,925 INFO: Microblog startup [in /home/kodi/Workspace/parky/app/__init__.py:52]
2018-07-05 00:29:05,881 INFO: Microblog startup [in /home/kodi/Workspace/parky/app/__init__.py:52]
2018-07-05 00:29:58,882 INFO: Microblog startup [in /home/kodi/Workspace/parky/app/__init__.py:52]
2018-07-05 00:30:53,471 INFO: Microblog startup [in /home/kodi/Workspace/parky/app/__init__.py:52]
2018-07-05 02:38:31,033 INFO: Microblog startup [in /home/kodi/Workspace/parky/app/__init__.py:58]
2018-07-05 02:38:42,357 ERROR: Exception on /label [GET] [in /home/kodi/Workspace/parky/venv/lib/python3.6/site-packages/flask/app.py:1761]
Traceback (most recent call last):
  File "/home/kodi/Workspace/parky/venv/lib/python3.6/site-packages/flask/app.py", line 2292, in wsgi_app
    response = self.full_dispatch_request()
  File "/home/kodi/Workspace/parky/venv/lib/python3.6/site-packages/flask/app.py", line 1815, in full_dispatch_request
    rv = self.handle_user_exception(e)
  File "/home/kodi/Workspace/parky/venv/lib/python3.6/site-packages/flask/app.py", line 1718, in handle_user_exception
    reraise(exc_type, exc_value, tb)
  File "/home/kodi/Workspace/parky/venv/lib/python3.6/site-packages/flask/_compat.py", line 35, in reraise
    raise value
  File "/home/kodi/Workspace/parky/venv/lib/python3.6/site-packages/flask/app.py", line 1813, in full_dispatch_request
    rv = self.dispatch_request()
  File "/home/kodi/Workspace/parky/venv/lib/python3.6/site-packages/flask/app.py", line 1799, in dispatch_request
    return self.view_functions[rule.endpoint](**req.view_args)
  File "/home/kodi/Workspace/parky/venv/lib/python3.6/site-packages/flask_login/utils.py", line 261, in decorated_view
    return func(*args, **kwargs)
  File "/home/kodi/Workspace/parky/app/routes.py", line 143, in label
    return render_template('label.html', list=list)
  File "/home/kodi/Workspace/parky/venv/lib/python3.6/site-packages/flask/templating.py", line 135, in render_template
    context, ctx.app)
  File "/home/kodi/Workspace/parky/venv/lib/python3.6/site-packages/flask/templating.py", line 117, in _render
    rv = template.render(context)
  File "/home/kodi/Workspace/parky/venv/lib/python3.6/site-packages/jinja2/asyncsupport.py", line 76, in render
    return original_render(self, *args, **kwargs)
  File "/home/kodi/Workspace/parky/venv/lib/python3.6/site-packages/jinja2/environment.py", line 1008, in render
    return self.environment.handle_exception(exc_info, True)
  File "/home/kodi/Workspace/parky/venv/lib/python3.6/site-packages/jinja2/environment.py", line 780, in handle_exception
    reraise(exc_type, exc_value, tb)
  File "/home/kodi/Workspace/parky/venv/lib/python3.6/site-packages/jinja2/_compat.py", line 37, in reraise
    raise value.with_traceback(tb)
  File "/home/kodi/Workspace/parky/app/templates/label.html", line 1, in top-level template code
    {% extends "base.html" %}
  File "/home/kodi/Workspace/parky/app/templates/base.html", line 23, in top-level template code
    <a href="{{ url_for('user', username=current_user.username) }}">{{current_user.username}}</a>
  File "/home/kodi/Workspace/parky/venv/lib/python3.6/site-packages/flask/helpers.py", line 356, in url_for
    return appctx.app.handle_url_build_error(error, endpoint, values)
  File "/home/kodi/Workspace/parky/venv/lib/python3.6/site-packages/flask/app.py", line 2061, in handle_url_build_error
    reraise(exc_type, exc_value, tb)
  File "/home/kodi/Workspace/parky/venv/lib/python3.6/site-packages/flask/_compat.py", line 35, in reraise
    raise value
  File "/home/kodi/Workspace/parky/venv/lib/python3.6/site-packages/flask/helpers.py", line 345, in url_for
    force_external=external)
  File "/home/kodi/Workspace/parky/venv/lib/python3.6/site-packages/werkzeug/routing.py", line 1776, in build
    raise BuildError(endpoint, values, method, self)
werkzeug.routing.BuildError: Could not build url for endpoint 'user' with values ['username']. Did you mean 'auth.user' instead?
2018-07-05 02:43:53,509 INFO: Microblog startup [in /home/kodi/Workspace/parky/app/__init__.py:58]
2018-07-05 02:55:07,886 INFO: Microblog startup [in /home/kodi/Workspace/parky/app/__init__.py:61]
